#VRML_SIM R2023a utf8

EXTERNPROTO "https://raw.githubusercontent.com/cyberbotics/webots/R2023a/projects/objects/trees/protos/BigSassafras.proto"
EXTERNPROTO "https://raw.githubusercontent.com/cyberbotics/webots/R2023a/projects/objects/trees/protos/Cypress.proto"
EXTERNPROTO "https://raw.githubusercontent.com/cyberbotics/webots/R2023a/projects/appearances/protos/DryMud.proto"
EXTERNPROTO "https://raw.githubusercontent.com/cyberbotics/webots/R2023a/projects/objects/trees/protos/Oak.proto"
EXTERNPROTO "https://raw.githubusercontent.com/cyberbotics/webots/R2023a/projects/appearances/protos/PaintedWood.proto"
EXTERNPROTO "https://raw.githubusercontent.com/cyberbotics/webots/R2023a/projects/objects/trees/protos/Pine.proto"
EXTERNPROTO "https://raw.githubusercontent.com/cyberbotics/webots/R2023a/projects/appearances/protos/Rubber.proto"
EXTERNPROTO "https://raw.githubusercontent.com/cyberbotics/webots/R2023a/projects/objects/trees/protos/SimpleTree.proto"
EXTERNPROTO "https://raw.githubusercontent.com/cyberbotics/webots/R2023a/projects/objects/backgrounds/protos/TexturedBackground.proto"
EXTERNPROTO "https://raw.githubusercontent.com/cyberbotics/webots/R2023a/projects/objects/backgrounds/protos/TexturedBackgroundLight.proto"
EXTERNPROTO "https://raw.githubusercontent.com/cyberbotics/webots/R2023a/projects/objects/floors/protos/UnevenTerrain.proto"

WorldInfo {
}
Viewpoint {
  orientation -0.21918647361444057 0.10683450094577318 0.9698163120880848 2.258462461862625
  position 44.82003832850924 -47.658864259460984 36.882459849255355
}
TexturedBackground {
}
TexturedBackgroundLight {
}
Robot {
  translation 0.3904274697675625 9.600818123768507 4.535592907274637
  rotation 0.04160184116156062 -0.03804821690391113 -0.9984095452280097 -0.8034913268355472
  children [
    DEF base Shape {
      appearance PaintedWood {
        colorOverride 0 0.2 0.1
      }
      geometry DEF Base Box {
        size 1.2 3 1
      }
    }
    Solid {
      translation 0 -1.26 0.55
      children [
        DEF cam_stand Shape {
          appearance PBRAppearance {
            baseColor 0.3 0.3 0.3
          }
          geometry Box {
            size 0.3 0.3 0.1
          }
        }
        Camera {
          translation 0 0 0.13
          rotation 0 0 1 -1.5707953071795862
          children [
            DEF cam Shape {
              appearance PBRAppearance {
              }
              geometry Box {
                size 0.1 0.1 0.1
              }
            }
          ]
          boundingObject USE cam
          physics Physics {
            mass 1
          }
        }
      ]
      name "solid(4)"
      boundingObject USE cam_stand
      physics Physics {
        mass 1
      }
    }
    DistanceSensor {
      translation 0.35 -1.5 0
      rotation 0 0 1 -1.5707853071795865
      children [
        DEF ds Shape {
          appearance PBRAppearance {
            baseColor 1 1 0
            metalness 0
          }
          geometry Sphere {
            radius 0.1
          }
        }
      ]
      name "ds_right"
      boundingObject DEF ds Shape {
        appearance PBRAppearance {
          baseColor 1 1 0
          metalness 0
        }
        geometry Sphere {
          radius 0.1
        }
      }
      physics DEF phy2 Physics {
        mass 1
      }
      lookupTable [
        0 0 0
        3 1000 0
      ]
      numberOfRays 2
    }
    DistanceSensor {
      translation -0.35 -1.5 0
      rotation 0 0 -1 1.57079
      children [
        DEF ds Shape {
          appearance PBRAppearance {
            baseColor 1 1 0
            metalness 0
          }
          geometry Sphere {
            radius 0.1
          }
        }
      ]
      name "ds_left"
      lookupTable [
        0 0 0
        3 1000 0
      ]
      numberOfRays 2
    }
    DEF wheel1 HingeJoint {
      jointParameters HingeJointParameters {
        position 827.2747273767818
        anchor 0.75 -0.96 -0.53
      }
      device [
        RotationalMotor {
          name "wheel1"
          maxTorque 50
        }
      ]
      endPoint Solid {
        translation 0.7500545661775462 -0.96000298987213 -0.5300173695964279
        rotation -0.6567922000092747 0.37046238957924077 -0.6567964859179862 2.4320341603814035
        children [
          DEF wheel Shape {
            appearance Rubber {
            }
            geometry Cylinder {
              height 0.5
              radius 0.5
            }
          }
        ]
        boundingObject USE wheel
        physics DEF phy1 Physics {
          mass 1
        }
        linearVelocity 1.4396917177189428 -1.40795240466285 0.049144728594098956
        angularVelocity 2.8172523746417335 2.875043232191505 -0.16381967048645107
      }
    }
    DEF wheel2 HingeJoint {
      jointParameters HingeJointParameters {
        position 893.0647440048476
        anchor -0.75 -0.96 -0.53
      }
      device [
        RotationalMotor {
          name "wheel2"
          maxTorque 50
        }
      ]
      endPoint Solid {
        translation -0.7500442815454464 -0.9599614084006255 -0.5299853733584354
        rotation -0.3803822862175338 -0.8429720422196709 -0.38040432748316577 4.542392631834508
        children [
          DEF wheel Shape {
            appearance Rubber {
            }
            geometry Cylinder {
              height 0.5
              radius 0.5
            }
          }
        ]
        name "solid(1)"
        boundingObject USE wheel
        physics USE phy1
        linearVelocity 1.43908689409964 -1.4096011492509457 0.010850408264045035
        angularVelocity 2.8172328653035947 2.875001938202285 -0.16373944348641736
      }
    }
    DEF wheel3 HingeJoint {
      jointParameters HingeJointParameters {
        position 810.8459147293147
        anchor 0.75 0.96 -0.53
      }
      device [
        RotationalMotor {
          name "wheel3"
          maxTorque 50
        }
      ]
      endPoint Solid {
        translation 0.7500226838697834 0.960059715009053 -0.529998469462526
        rotation -0.15091778026645017 -0.9769579361301011 -0.15092055735339904 4.68906971574858
        children [
          DEF wheel Shape {
            appearance Rubber {
            }
            geometry Cylinder {
              height 0.5
              radius 0.5
            }
          }
        ]
        name "solid(2)"
        boundingObject USE wheel
        physics USE phy1
        linearVelocity 1.440531296076907 -1.4055772210535966 0.10400402475994226
        angularVelocity 2.817252578271167 2.875029005755405 -0.16375212675608264
      }
    }
    DEF wheel4 HingeJoint {
      jointParameters HingeJointParameters {
        position 884.9602503674232
        anchor -0.75 0.96 -0.53
      }
      device [
        RotationalMotor {
          name "wheel4"
          maxTorque 50
        }
      ]
      endPoint Solid {
        translation -0.7500744885430137 0.9600554911718275 -0.5299779358407061
        rotation 0.4237130327852963 -0.8006010428308488 0.42368058259264596 4.491811472187564
        children [
          DEF wheel Shape {
            appearance Rubber {
            }
            geometry Cylinder {
              height 0.5
              radius 0.5
            }
          }
        ]
        name "solid(3)"
        boundingObject USE wheel
        physics USE phy1
        linearVelocity 1.4399188531066367 -1.407209678738202 0.06565351596721242
        angularVelocity 2.817264075125466 2.8750358815089134 -0.1637186226611697
      }
    }
  ]
  boundingObject USE base
  physics USE phy1
  controller "my_controller"
  linearVelocity 1.4416614584676857 -1.4407485721213997 0.032204841289852154
  angularVelocity 0.03822454520231291 0.0026737404658667713 -0.0007222090468844527
}
DEF forest Solid {
  children [
    Pine {
      translation -15.62 20.85 1.15
      name "pine tree(6)"
    }
    Pine {
      translation -15.62 -10.45 1.15
      name "pine tree(5)"
    }
    Pine {
      translation 11.67 -10.45 1.45
      name "pine tree(3)"
    }
    Pine {
      translation 20.49 -10.45 2.81
      name "pine tree(4)"
    }
    Pine {
      translation 11.67 15.84 1.88
      name "pine tree(2)"
    }
    Pine {
      translation -4.35 9.25 2.22
      name "pine tree(1)"
    }
    Pine {
      translation -4.35 -3.53 2.18
    }
    SimpleTree {
      translation 0 0 3
    }
    SimpleTree {
      translation 6 0 3
      name "tree(1)"
    }
    SimpleTree {
      translation 6 10 3
      name "tree(2)"
    }
    SimpleTree {
      translation 16 15 3
      name "tree(3)"
    }
    SimpleTree {
      translation -16 -15 1.8
      name "tree(4)"
    }
    SimpleTree {
      translation 16 -15 3
      name "tree(5)"
    }
    SimpleTree {
      translation 5 -22 2
      name "tree(6)"
    }
    SimpleTree {
      translation -15 -22 2
      name "tree(7)"
    }
    SimpleTree {
      translation -9 22 2
      name "tree(8)"
    }
    SimpleTree {
      translation -18 16 2.5
      name "tree(9)"
    }
    SimpleTree {
      translation -22 -3 2
      name "tree(10)"
    }
    SimpleTree {
      translation 10 -8 3
      name "tree(11)"
    }
    SimpleTree {
      translation -5 -8 2.3
      name "tree(12)"
    }
    SimpleTree {
      translation 1 -17 2
      name "tree(13)"
    }
    Oak {
      translation 14.94 0 3.24
    }
    Oak {
      translation 20 -5.97 3.28
      name "oak tree(1)"
    }
    Oak {
      translation 15.97 -10.75 3.02
      name "oak tree(2)"
    }
    Oak {
      translation 15.97 11.04 3.07
      name "oak tree(3)"
    }
    Oak {
      translation -24.52 6.27 2.46
      name "oak tree(4)"
    }
    Oak {
      translation -12.06 2.39 2.09
      name "oak tree(6)"
    }
    Oak {
      translation -13.84 10.96 2.09
      name "oak tree(7)"
    }
    Oak {
      translation -2.97 18.97 1.79
      name "oak tree(8)"
    }
    Oak {
      translation 0.35 13.07 2.24
      name "oak tree(9)"
    }
    Oak {
      translation -9.22 15.64 2.72
      name "oak tree(5)"
    }
    Oak {
      translation 7.46 20.45 2.43
      name "oak tree(10)"
    }
    Oak {
      translation 16.74 21.4 2.43
      name "oak tree(11)"
    }
    BigSassafras {
      translation -11.82 -13.71 1.72
    }
    BigSassafras {
      translation -21.32 -8.95 1.72
      name "sassafras tree(1)"
    }
    BigSassafras {
      translation 19.67 7.95 3.44
      name "sassafras tree(2)"
    }
    BigSassafras {
      translation 19.67 -1.13 2.97
      name "sassafras tree(3)"
    }
    BigSassafras {
      translation 21.66 -19.93 2.97
      name "sassafras tree(4)"
    }
    BigSassafras {
      translation 9.84 -19.93 2.64
      name "sassafras tree(5)"
    }
    BigSassafras {
      translation -6.69 -19.93 1.29
      name "sassafras tree(6)"
    }
    BigSassafras {
      translation -16.82 -5.16 2.98
      name "sassafras tree(7)"
    }
    BigSassafras {
      translation -16.82 8.12 2.98
      name "sassafras tree(8)"
    }
    BigSassafras {
      translation -21.82 21.14 2.98
      name "sassafras tree(9)"
    }
    BigSassafras {
      translation 1.95 21.14 2.63
      name "sassafras tree(10)"
    }
    Cypress {
      translation -11.36 0 1.96
    }
    Cypress {
      translation -14.16 5.78 2.06
      name "cypress tree(1)"
    }
    Cypress {
      translation 20.42 15.8 3.01
      name "cypress tree(2)"
    }
    Cypress {
      translation 21.87 20.79 3.01
      name "cypress tree(3)"
    }
    Cypress {
      translation 11.51 1.81 3.01
      name "cypress tree(4)"
    }
    Cypress {
      translation 2.77 -10.75 2.51
      name "cypress tree(5)"
    }
    Cypress {
      translation -2.24 -21.57 1.87
      name "cypress tree(6)"
    }
    Cypress {
      translation 15.22 -21.57 2.5
      name "cypress tree(7)"
    }
    Cypress {
      translation 6.61 -15.53 2.8
      name "cypress tree(8)"
    }
    Cypress {
      translation -11.26 5.51 2.26
      name "cypress tree(9)"
    }
  ]
}
UnevenTerrain {
}
DEF Border Solid {
  translation 0 0 3.9
  children [
    Solid {
      translation -1.3792605042786385e-07 -25.20000062547894 -0.3700941938973754
      rotation -0.03020900480594554 -0.10649179629172535 0.9938545735424252 1.1643902325295737e-05
      children [
        DEF border Shape {
          appearance DryMud {
          }
          geometry Box {
            size 49 1 3
          }
        }
      ]
      name "border1"
      boundingObject USE border
      physics DEF phy1 Physics {
        mass 1
      }
      linearVelocity 7.174711454672686e-131 -2.0881342854511737e-231 -1.2139209860606136e-07
      angularVelocity -2.659706904615283e-26 2.6469803600921094e-21 2.1175823223600454e-20
    }
    Solid {
      translation -4.472205634914091e-08 25.53000006670277 -0.3700940919761906
      rotation 0.007083300823455552 -0.48715232049618196 0.8732882934544753 8.820099222355453e-07
      children [
        DEF border Shape {
          appearance DryMud {
          }
          geometry Box {
            size 49 1 3
          }
        }
      ]
      name "border2"
      boundingObject USE border
      physics USE phy1
      linearVelocity 3.494251921146101e-07 -5.211662628090167e-07 -2.9208347359586857e-07
      angularVelocity -4.881289202431753e-08 3.4253742752604214e-06 -6.140034942366487e-06
    }
    Solid {
      translation 25.53 0 -0.37
      rotation 0 0 1 1.5708
      children [
        DEF border Shape {
          appearance DryMud {
          }
          geometry Box {
            size 49 1 3
          }
        }
      ]
      name "border3"
      boundingObject USE border
    }
    Solid {
      translation -25.5301 1.57462e-05 -0.3700941138225531
      rotation 5.1580022398749126e-05 -9.550089548459884e-05 0.9999999941095401 1.569814080916819
      children [
        DEF border Shape {
          appearance DryMud {
          }
          geometry Box {
            size 49 1 3
          }
        }
      ]
      name "border4"
      boundingObject USE border
      physics USE phy1
      linearVelocity 0 0 -1.2139209860606136e-07
    }
  ]
  name "solid(1)"
}
